GPU available: True, used: False
TPU available: False, using: 0 TPU cores
IPU available: False, using: 0 IPUs
/usr/local/lib/python3.6/dist-packages/pytorch_lightning/trainer/trainer.py:1585: UserWarning: GPU available but not used. Set the gpus flag in your trainer `Trainer(gpus=1)` or script `--gpus=1`.
  "GPU available but not used. Set the gpus flag in your trainer `Trainer(gpus=1)` or script `--gpus=1`."
GPU available: True, used: True
TPU available: False, using: 0 TPU cores
IPU available: False, using: 0 IPUs
Traceback (most recent call last):
  File "/usr/local/lib/python3.6/dist-packages/pytorch_lightning/utilities/parsing.py", line 272, in __getattr__
    return self[key]
KeyError: 'batch_size'
The above exception was the direct cause of the following exception:
Traceback (most recent call last):
  File "trainer.py", line 135, in <module>
    main()
  File "trainer.py", line 129, in main
    trainer.fit(landclassifier)
  File "/usr/local/lib/python3.6/dist-packages/pytorch_lightning/trainer/trainer.py", line 741, in fit
    self._fit_impl, model, train_dataloaders, val_dataloaders, datamodule, ckpt_path
  File "/usr/local/lib/python3.6/dist-packages/pytorch_lightning/trainer/trainer.py", line 685, in _call_and_handle_interrupt
    return trainer_fn(*args, **kwargs)
  File "/usr/local/lib/python3.6/dist-packages/pytorch_lightning/trainer/trainer.py", line 777, in _fit_impl
    self._run(model, ckpt_path=ckpt_path)
  File "/usr/local/lib/python3.6/dist-packages/pytorch_lightning/trainer/trainer.py", line 1131, in _run
    self._data_connector.prepare_data()
  File "/usr/local/lib/python3.6/dist-packages/pytorch_lightning/trainer/connectors/data_connector.py", line 168, in prepare_data
    self.trainer.call_hook("prepare_data")
  File "/usr/local/lib/python3.6/dist-packages/pytorch_lightning/trainer/trainer.py", line 1501, in call_hook
    output = model_fx(*args, **kwargs)
  File "trainer.py", line 56, in prepare_data
    self.train_loader, self.valid_loader = get_eurosat_dataloaders(batch_size=self.hparams.batch_size,
  File "/usr/local/lib/python3.6/dist-packages/pytorch_lightning/utilities/parsing.py", line 274, in __getattr__
    raise AttributeError(f'Missing attribute "{key}"') from exp
AttributeError: Missing attribute "batch_size"